Traceback (most recent call last):
  File "Execute/repeat-ins.py", line 117, in <module>
    main()
  File "Execute/repeat-ins.py", line 38, in main
    rep = sys.argv[2]
IndexError: list index out of range
real         0.02
user         0.01
sys          0.01
Traceback (most recent call last):
  File "Execute/repeat-ins.py", line 117, in <module>
    main()
  File "Execute/repeat-ins.py", line 38, in main
    rep = sys.argv[2]
IndexError: list index out of range
real         0.02
user         0.01
sys          0.01
